Workbook
Name FloorPlanRate: Assumptions!$B$2
Name IncentiveRateToyota: Assumptions!$B$3
Name IncentiveRateHonda: Assumptions!$B$4
Name IncentiveRateFord: Assumptions!$B$5
Name FI_PVR_Target: Assumptions!$B$6
Name ServiceAbsorptionTarget: Assumptions!$B$7
Name TaxRate: Assumptions!$B$8
Name OwnerCompensationAddback: Assumptions!$B$10
Name OneTimeLegalCosts: Assumptions!$B$11
Name OverheadBase: Assumptions!$B$14

Sheet P&L Summary
A1: Line Item | B1: Jan | C1: Feb | D1: Mar | E1: Apr | F1: May | G1: Jun | H1: Jul | I1: Aug | J1: Sep | K1: Oct | L1: Nov | M1: Dec | N1: YTD | O1: Budget
A2: New Vehicle Sales | B2: 126736 | C2: 154062 | D2: 175089 | E2: 169177 | F2: 120113 | G2: 141543 | H2: 174281 | I2: 116714 | J2: 122225 | K2: 148946 | L2: 101019 | M2: 110379
A3: Used Vehicle Sales | B3: 95903 | C3: 90434 | D3: 61629 | E3: 80484 | F3: 112719 | G3: 61340 | H3: 170473 | I3: 78535 | J3: 80211 | K3: 86723 | L3: 156929 | M3: 102482
A4: F&I Income | B4: 184556 | C4: 167530 | D4: 186445 | E4: 104186 | F4: 56352 | G4: 80886 | H4: 107659 | I4: 89633 | J4: 124602 | K4: 77039 | L4: 109237 | M4: 33708
A5: Service Revenue | B5: 170020 | C5: 63182 | D5: 101909 | E5: 41931 | F5: 44293 | G5: 175059 | H5: 106581 | I5: 63103 | J5: 197213 | K5: 158680 | L5: 56892 | M5: 33215
A6: Parts Revenue | B6: 180487 | C6: 104537 | D6: 153049 | E6: 155492 | F6: 145466 | G6: 119314 | H6: 78329 | I6: 43468 | J6: 96185 | K6: 155233 | L6: 59907 | M6: 47129
A10: Total Revenue | B10: =SUM(B2:B6) | C10: =SUM(C2:C6) | D10: =SUM(D2:D6) | E10: =SUM(E2:E6) | F10: =SUM(F2:F6) | G10: =SUM(G2:G6) | H10: =SUM(H2:H6) | I10: =SUM(I2:I6) | ... M10: =SUM(M2:M6)
A12: New Vehicle Gross | B12: ='New Vehicle'!B65 | C12: ='New Vehicle'!B66 | D12: ='New Vehicle'!B67 | E12: ='New Vehicle'!B68 | F12: ='New Vehicle'!B69 | G12: ='New Vehicle'!B70 | H12: ='New Vehicle'!B71 | I12: ='New Vehicle'!B72 | J12: ='New Vehicle'!B73 | K12: ='New Vehicle'!B74 | L12: ='New Vehicle'!B75 | M12: ='New Vehicle'!B76
A13: Used Vehicle Gross | B13: ='Used Vehicle'!B45 | C13: ='Used Vehicle'!B46 | D13: ='Used Vehicle'!B47 | E13: ='Used Vehicle'!B48 | F13: ='Used Vehicle'!B49 | G13: ='Used Vehicle'!B50 | H13: ='Used Vehicle'!B51 | I13: ='Used Vehicle'!B52 | J13: ='Used Vehicle'!B53 | K13: ='Used Vehicle'!B54 | L13: ='Used Vehicle'!B55 | M13: ='Used Vehicle'!B56
A14: F&I Gross | B14: ='F&I Detail'!B60 | C14: ='F&I Detail'!B61 | D14: ='F&I Detail'!B62 | E14: ='F&I Detail'!B63 | F14: ='F&I Detail'!B64 | G14: ='F&I Detail'!B65 | H14: ='F&I Detail'!B66 | I14: ='F&I Detail'!B67 | J14: ='F&I Detail'!B68 | K14: ='F&I Detail'!B69 | L14: ='F&I Detail'!B70 | M14: ='F&I Detail'!B71
A15: Service & Parts Gross | B15: ='Service & Parts'!B60 | C15: ='Service & Parts'!B61 | D15: ='Service & Parts'!B62 | E15: ='Service & Parts'!B63 | F15: ='Service & Parts'!B64 | G15: ='Service & Parts'!B65 | H15: ='Service & Parts'!B66 | I15: ='Service & Parts'!B67 | J15: ='Service & Parts'!B68 | K15: ='Service & Parts'!B69 | L15: ='Service & Parts'!B70 | M15: ='Service & Parts'!B71
A18: Total Gross Profit | B18: =SUM(B12:B15) | C18: =SUM(C12:C15) | D18: =SUM(D12:D15) | E18: =SUM(E12:E15) | F18: =SUM(F12:F15) | G18: =SUM(G12:G15) | H18: =SUM(H12:H15) | I18: =SUM(I12:I15) | ... M18: =SUM(M12:M15)
A22: Salaries | B22: 18130 | C22: 21113 | D22: 7427 | E22: 23907 | F22: 25625 | G22: 27493 | H22: 6756 | I22: 9971 | J22: 9888 | K22: 23443 | L22: 14956 | M22: 7791
A23: Floor Plan Interest | B23: 13132 | C23: 8881 | D23: 23286 | E23: 18637 | F23: 24867 | G23: 24533 | H23: 25264 | I23: 12395 | J23: 22123 | K23: 17464 | L23: 19762 | M23: 19507
A24: Advertising | B24: 14743 | C24: 24284 | D24: 19051 | E24: 15006 | F24: 23632 | G24: 25349 | H24: 6973 | I24: 24976 | J24: 29251 | K24: 8251 | L24: 29993 | M24: 11808
A25: Rent | B25: 25496 | C25: 11914 | D25: 13671 | E25: 26640 | F25: 7660 | G25: 10146 | H25: 12859 | I25: 10695 | J25: 23087 | K25: 7459 | L25: 10129 | M25: 5087
A26: Utilities | B26: 18386 | C26: 19762 | D26: 27589 | E26: 24458 | F26: 20398 | G26: 14543 | H26: 6069 | I26: 12585 | J26: 14440 | K26: 28165 | L26: 14264 | M26: 28035
A27: Other | B27: 19877 | C27: 7332 | D27: 27524 | E27: 12648 | F27: 13668 | G27: 25481 | H27: 24326 | I27: 26665 | J27: 11482 | K27: 18930 | L27: 8760 | M27: 22844
A29: Total Operating Expenses | B29: =SUM(B22:B27) | C29: =SUM(C22:C27) | D29: =SUM(D22:D27) | E29: =SUM(E22:E27) | F29: =SUM(F22:F27) | G29: =SUM(G22:G27) | H29: =SUM(H22:H27) | I29: =SUM(I22:I27) | ... M29: =SUM(M22:M27)
A30: Total Overhead | B30: =B29+OverheadBase*'Service & Parts'!B75 | C30: =C29+OverheadBase*'Service & Parts'!B75 | D30: =D29+OverheadBase*'Service & Parts'!B75 | E30: =E29+OverheadBase*'Service & Parts'!B75 | F30: =F29+OverheadBase*'Service & Parts'!B75 | G30: =G29+OverheadBase*'Service & Parts'!B75 | H30: =H29+OverheadBase*'Service & Parts'!B75 | I30: =I29+OverheadBase*'Service & Parts'!B75 | J30: =J29+OverheadBase*'Service & Parts'!B75 | K30: =K29+OverheadBase*'Service & Parts'!B75 | L30: =L29+OverheadBase*'Service & Parts'!B75 | M30: =M29+OverheadBase*'Service & Parts'!B75
A32: Adjusted EBITDA | B32: =B18-B29+OwnerCompensationAddback+OneTimeLegalCosts | C32: =C18-C29+OwnerCompensationAddback+OneTimeLegalCosts | D32: =D18-D29+OwnerCompensationAddback+OneTimeLegalCosts | E32: =E18-E29+OwnerCompensationAddback+OneTimeLegalCosts | F32: =F18-F29+OwnerCompensationAddback+OneTimeLegalCosts | G32: =G18-G29+OwnerCompensationAddback+OneTimeLegalCosts | H32: =H18-H29+OwnerCompensationAddback+OneTimeLegalCosts | I32: =I18-I29+OwnerCompensationAddback+OneTimeLegalCosts | ... M32: =M18-M29+OwnerCompensationAddback+OneTimeLegalCosts
A35: Net Income | B35: =B32*(1-TaxRate) | C35: =C32*(1-TaxRate) | D35: =D32*(1-TaxRate) | E35: =E32*(1-TaxRate) | F35: =F32*(1-TaxRate) | G35: =G32*(1-TaxRate) | H35: =H32*(1-TaxRate) | I35: =I32*(1-TaxRate) | ... M35: =M32*(1-TaxRate)

Sheet Assumptions
A1: Assumption | B1: Value | C1: Effective Date | D1: Notes
A2: FloorPlanRate | B2: 0.058 | C2: 45809 | D2: Floor plan interest annual rate
A3: IncentiveRateToyota | B3: 0.021 | C3: 45884 | D3: OEM incentive for Toyota
A4: IncentiveRateHonda | B4: 0.018 | C4: 45884 | D4: OEM incentive for Honda
A5: IncentiveRateFord | B5: 0.025 | C5: 45884 | D5: OEM incentive for Ford
A6: FI_PVR_Target | B6: 1600 | C6: 45667 | D6: Target finance & insurance PVR
A7: ServiceAbsorptionTarget | B7: 0.8 | C7: 44967 | D7: Target absorption — STALE
A8: TaxRate | B8: 0.21 | C8: 45017 | D8: Federal tax rate — STALE
A9: OverheadAllocationMethod | B9: revenue-weighted | C9: 45657 | D9: How overhead is allocated
A10: OwnerCompensationAddback | B10: 8000 | C10: 45611 | D10: EBITDA addback
A11: OneTimeLegalCosts | B11: 5000 | C11: 45611 | D11: EBITDA addback
A12: DEPRECATED_FloorPlanRateOld | B12: 0.065 | C12: 44713 | D12: Old rate — DO NOT USE
A13: DEPRECATED_HoldbackRate | B13: 0.03 | C13: 44562 | D13: Old holdback — hidden
A14: OverheadBase | B14: 120000 | C14: 45292 | D14: Base overhead for absorption calc

Sheet New Vehicle
A1: Stock# | B1: VIN | C1: Sale Date | D1: Sale Price | E1: Invoice Cost | F1: Holdback | G1: Incentive Allocation | H1: Front Gross | I1: F&I Revenue | J1: Month | K1: OEM
A2: 1002 | B2: VIN00001002 | C2: 46029 | D2: 34476 | E2: 32748 | F2: 654.96 | G2: =D2*IncentiveRateFord | H2: =D2-E2+F2+G2 | I2: 1151 | J2: Jan | K2: Ford
A3: 1003 | B3: VIN00001003 | C3: 46061 | D3: 28506 | E3: 26505 | F3: 530.1 | G3: =D3*IncentiveRateToyota | H3: =D3-E3+F3+G3 | I3: 1557 | J3: Feb | K3: Toyota
A4: 1004 | B4: VIN00001004 | C4: 46090 | D4: 26286 | E4: 23278 | F4: 465.56 | G4: =D4*IncentiveRateHonda | H4: =D4-E4+F4+G4 | I4: 1309 | J4: Mar | K4: Honda
A5: 1005 | B5: VIN00001005 | C5: 46122 | D5: 35087 | E5: 32071 | F5: 641.42 | G5: =D5*IncentiveRateFord | H5: =D5-E5+F5+G5 | I5: 1278 | J5: Apr | K5: Ford
A6: 1006 | B6: VIN00001006 | C6: 46153 | D6: 33674 | E6: 31310 | F6: 626.2 | G6: =D6*IncentiveRateToyota | H6: =D6-E6+F6+G6 | I6: 1165 | J6: May | K6: Toyota
A7: 1007 | B7: VIN00001007 | C7: 46185 | D7: 24488 | E7: 22797 | F7: 455.94 | G7: =D7*IncentiveRateHonda | H7: =D7-E7+F7+G7 | I7: 1547 | J7: Jun | K7: Honda
A8: 1008 | B8: VIN00001008 | C8: 46216 | D8: 27811 | E8: 25277 | F8: 505.54 | G8: =D8*IncentiveRateFord | H8: =D8-E8+F8+G8 | I8: 1154 | J8: Jul | K8: Ford
A9: 1009 | B9: VIN00001009 | C9: 46248 | D9: 33195 | E9: 31288 | F9: 625.76 | G9: =D9*IncentiveRateToyota | H9: =D9-E9+F9+G9 | I9: 1959 | J9: Aug | K9: Toyota
A10: 1010 | B10: VIN00001010 | C10: 46280 | D10: 27611 | E10: 25192 | F10: 503.84 | G10: =D10*IncentiveRateHonda | H10: =D10-E10+F10+G10 | I10: 1669 | J10: Sep | K10: Honda
A11: 1011 | B11: VIN00001011 | C11: 46311 | D11: 24106 | E11: 21052 | F11: 421.04 | G11: =D11*IncentiveRateFord | H11: =D11-E11+F11+G11 | I11: 1426 | J11: Oct | K11: Ford
A12: 1012 | B12: VIN00001012 | C12: 46343 | D12: 35438 | E12: 33073 | F12: 661.46 | G12: =D12*IncentiveRateToyota | H12: =D12-E12+F12+G12 | I12: 1796 | J12: Nov | K12: Toyota
A13: 1013 | B13: VIN00001013 | C13: 46374 | D13: 28552 | E13: 26734 | F13: 534.68 | G13: =D13*IncentiveRateHonda | H13: =D13-E13+F13+G13 | I13: 1540 | J13: Dec | K13: Honda
A14: 1014 | B14: VIN00001014 | C14: 46041 | D14: 29514 | E14: 27805 | F14: 556.1 | G14: =D14*IncentiveRateFord | H14: =D14-E14+F14+G14 | I14: 1289 | J14: Jan | K14: Ford
A15: 1015 | B15: VIN00001015 | C15: 46073 | D15: 30224 | E15: 28526 | F15: 570.52 | G15: =D15*IncentiveRateToyota | H15: =D15-E15+F15+G15 | I15: 1835 | J15: Feb | K15: Toyota
A16: 1016 | B16: VIN00001016 | C16: 46102 | D16: 29635 | E16: 26899 | F16: 537.98 | G16: =D16*IncentiveRateHonda | H16: =D16-E16+F16+G16 | I16: 1641 | J16: Mar | K16: Honda
A17: 1017 | B17: VIN00001017 | C17: 46134 | D17: 24711 | E17: 21717 | F17: 434.34 | G17: =D17*IncentiveRateFord | H17: =D17-E17+F17+G17 | I17: 2040 | J17: Apr | K17: Ford
A18: 1018 | B18: VIN00001018 | C18: 46165 | D18: 32785 | E18: 31030 | F18: 620.6 | G18: =D18*IncentiveRateToyota | H18: =D18-E18+F18+G18 | I18: 1875 | J18: May | K18: Toyota
A19: 1019 | B19: VIN00001019 | C19: 46197 | D19: 25291 | E19: 22661 | F19: 453.22 | G19: =D19*IncentiveRateHonda | H19: =D19-E19+F19+G19 | I19: 1700 | J19: Jun | K19: Honda
A20: 1020 | B20: VIN00001020 | C20: 46208 | D20: 34299 | E20: 31533 | F20: 630.66 | G20: =D20*IncentiveRateFord | H20: =D20-E20+F20+G20 | I20: 1840 | J20: Jul | K20: Ford
A21: 1021 | B21: VIN00001021 | C21: 46240 | D21: 33459 | E21: 31566 | F21: 631.32 | G21: =D21*IncentiveRateToyota | H21: =D21-E21+F21+G21 | I21: 1242 | J21: Aug | K21: Toyota
A22: 1022 | B22: VIN00001022 | C22: 46272 | D22: 24750 | E22: 21896 | F22: 437.92 | G22: =D22*IncentiveRateHonda | H22: =D22-E22+F22+G22 | I22: 1566 | J22: Sep | K22: Honda
A23: 1023 | B23: VIN00001023 | C23: 46303 | D23: 28741 | E23: 27078 | F23: 541.56 | G23: =D23*IncentiveRateFord | H23: =D23-E23+F23+G23 | I23: 1576 | J23: Oct | K23: Ford
A24: 1024 | B24: VIN00001024 | C24: 46335 | D24: 25654 | E24: 23376 | F24: 467.52 | G24: =D24*IncentiveRateToyota | H24: =D24-E24+F24+G24 | I24: 1669 | J24: Nov | K24: Toyota
A25: 1025 | B25: VIN00001025 | C25: 46366 | D25: 31428 | E25: 28627 | F25: 572.54 | G25: =D25*IncentiveRateHonda | H25: =D25-E25+F25+G25 | I25: 1847 | J25: Dec | K25: Honda
A26: 1026 | B26: VIN00001026 | C26: 46033 | D26: 26664 | E26: 24406 | F26: 488.12 | G26: =D26*IncentiveRateFord | H26: =D26-E26+F26+G26 | I26: 1827 | J26: Jan | K26: Ford
A27: 1027 | B27: VIN00001027 | C27: 46065 | D27: 27432 | E27: 24560 | F27: 491.2 | G27: =D27*IncentiveRateToyota | H27: =D27-E27+F27+G27 | I27: 1646 | J27: Feb | K27: Toyota
A28: 1028 | B28: VIN00001028 | C28: 46094 | D28: 35498 | E28: 32080 | F28: 641.6 | G28: =D28*IncentiveRateHonda | H28: =D28-E28+F28+G28 | I28: 1246 | J28: Mar | K28: Honda
A29: 1029 | B29: VIN00001029 | C29: 46126 | D29: 33980 | E29: 31180 | F29: 623.6 | G29: =D29*IncentiveRateFord | H29: =D29-E29+F29+G29 | I29: 1450 | J29: Apr | K29: Ford
A30: 1030 | B30: VIN00001030 | C30: 46157 | D30: 32751 | E30: 29758 | F30: 595.16 | G30: =D30*IncentiveRateToyota | H30: =D30-E30+F30+G30 | I30: 1601 | J30: May | K30: Toyota
A31: 1031 | B31: VIN00001031 | C31: 46189 | D31: 26677 | E31: 24231 | F31: 484.62 | G31: =D31*IncentiveRateHonda | H31: =D31-E31+F31+G31 | I31: 1877 | J31: Jun | K31: Honda
A32: 1032 | B32: VIN00001032 | C32: 46220 | D32: 28422 | E32: 25027 | F32: 500.54 | G32: =D32*IncentiveRateFord | H32: =D32-E32+F32+G32 | I32: 1549 | J32: Jul | K32: Ford
A33: 1033 | B33: VIN00001033 | C33: 46252 | D33: 35216 | E33: 33052 | F33: 661.04 | G33: =D33*IncentiveRateToyota | H33: =D33-E33+F33+G33 | I33: 1214 | J33: Aug | K33: Toyota
A34: 1034 | B34: VIN00001034 | C34: 46284 | D34: 27752 | E34: 24569 | F34: 491.38 | G34: =D34*IncentiveRateHonda | H34: =D34-E34+F34+G34 | I34: 1165 | J34: Sep | K34: Honda
A35: 1035 | B35: VIN00001035 | C35: 46315 | D35: 29168 | E35: 26847 | F35: 536.94 | G35: =D35*IncentiveRateFord | H35: =D35-E35+F35+G35 | I35: 1648 | J35: Oct | K35: Ford
A36: 1036 | B36: VIN00001036 | C36: 46347 | D36: 25084 | E36: 23152 | F36: 463.04 | G36: =D36*IncentiveRateToyota | H36: =D36-E36+F36+G36 | I36: 1744 | J36: Nov | K36: Toyota
A37: 1037 | B37: VIN00001037 | C37: 46378 | D37: 27483 | E37: 24641 | F37: 492.82 | G37: =D37*IncentiveRateHonda | H37: =D37-E37+F37+G37 | I37: 2122 | J37: Dec | K37: Honda
A38: 1038 | B38: VIN00001038 | C38: 46045 | D38: 30482 | E38: 27171 | F38: 543.42 | G38: =D38*IncentiveRateFord | H38: =D38-E38+F38+G38 | I38: 2039 | J38: Jan | K38: Ford
A39: 1039 | B39: VIN00001039 | C39: 46077 | D39: 26340 | E39: 24298 | F39: 485.96 | G39: =D39*IncentiveRateToyota | H39: =D39-E39+F39+G39 | I39: 1385 | J39: Feb | K39: Toyota
A40: 1040 | B40: VIN00001040 | C40: 46086 | D40: 28040 | E40: 25015 | F40: 500.3 | G40: =D40*IncentiveRateHonda | H40: =D40-E40+F40+G40 | I40: 1638 | J40: Mar | K40: Honda
...

Sheet Used Vehicle
A1: Stock# | B1: VIN | C1: Sale Date | D1: Sale Price | E1: Acquisition Cost | F1: Recon Cost | G1: Days on Lot | H1: Floor Plan Interest | I1: Adjusted Gross | J1: Month | K1: Source
A2: 2002 | B2: VIN_U0002002 | C2: 46034 | D2: 20930 | E2: 18032 | F2: 583 | G2: 80 | H2: =G2*E2*FloorPlanRate/365 | I2: =D2-E2-F2-H2 | J2: Jan | K2: Auction
A3: 2003 | B3: VIN_U0002003 | C3: 46066 | D3: 16489 | E3: 14297 | F3: 524 | G3: 34 | H3: =G3*E3*FloorPlanRate/365 | I3: =D3-E3-F3-H3 | J3: Feb | K3: Direct
A4: 2004 | B4: VIN_U0002004 | C4: 46095 | D4: 17621 | E4: 13892 | F4: 430 | G4: 64 | H4: =G4*E4*FloorPlanRate/365 | I4: =D4-E4-F4-H4 | J4: Mar | K4: Auction
A5: 2005 | B5: VIN_U0002005 | C5: 46127 | D5: 24763 | E5: 20846 | F5: 1383 | G5: 47 | H5: =G5*E5*FloorPlanRate/365 | I5: =D5-E5-F5-H5 | J5: Apr | K5: Direct
A6: 2006 | B6: VIN_U0002006 | C6: 46158 | D6: 15188 | E6: 12719 | F6: 1399 | G6: 49 | H6: =G6*E6*FloorPlanRate/365 | I6: =D6-E6-F6-H6 | J6: May | K6: Direct
A7: 2007 | B7: VIN_U0002007 | C7: 46190 | D7: 20573 | E7: 18117 | F7: 901 | G7: 70 | H7: =G7*E7*FloorPlanRate/365 | I7: =D7-E7-F7-H7 | J7: Jun | K7: Trade-in
A8: 2008 | B8: VIN_U0002008 | C8: 46221 | D8: 22433 | E8: 20420 | F8: 839 | G8: 79 | H8: =G8*E8*FloorPlanRate/365 | I8: =D8-E8-F8-H8 | J8: Jul | K8: Trade-in
A9: 2009 | B9: VIN_U0002009 | C9: 46253 | D9: 23317 | E9: 20882 | F9: 911 | G9: 79 | H9: =G9*E9*FloorPlanRate/365 | I9: =D9-E9-F9-H9 | J9: Aug | K9: Direct
A10: 2010 | B10: VIN_U0002010 | C10: 46285 | D10: 18258 | E10: 15632 | F10: 1065 | G10: 35 | H10: =G10*E10*FloorPlanRate/365 | I10: =D10-E10-F10-H10 | J10: Sep | K10: Direct
A11: 2011 | B11: VIN_U0002011 | C11: 46316 | D11: 23689 | E11: 21687 | F11: 963 | G11: 77 | H11: =G11*E11*FloorPlanRate/365 | I11: =D11-E11-F11-H11 | J11: Oct | K11: Trade-in
A12: 2012 | B12: VIN_U0002012 | C12: 46348 | D12: 16832 | E12: 13346 | F12: 929 | G12: 45 | H12: =G12*E12*FloorPlanRate/365 | I12: =D12-E12-F12-H12 | J12: Nov | K12: Trade-in
A13: 2013 | B13: VIN_U0002013 | C13: 46379 | D13: 18946 | E13: 14623 | F13: 461 | G13: 25 | H13: =G13*E13*FloorPlanRate/365 | I13: =D13-E13-F13-H13 | J13: Dec | K13: Direct
... A22: 2022 | B22: VIN_U0002022 | C22: 46282 | D22: 16160 | E22: 12055 | F22: 787 | G22: 50 | H22: =G22*E22*FloorPlanRate/365 | I22: =D22-E22-F22-H22 | J22: Sep | K22: Direct
A23: 2023 | B23: VIN_U0002023 | C23: 46313 | D23: 22953 | E23: 20076 | F23: 1404 | G23: 31 | H23: =G23*E23*FloorPlanRate/365 | I23: 3200 | J23: Oct | K23: Direct
A24: 2024 | B24: VIN_U0002024 | C24: 46345 | D24: 24355 | E24: 19995 | F24: 1268 | G24: 46 | H24: =G24*E24*FloorPlanRate/365 | I24: =D24-E24-F24-H24 | J24: Nov | K24: Auction
A25: 2025 | B25: VIN_U0002025 | C25: 46376 | D25: 21669 | E25: 18890 | F25: 493 | G25: 27 | H25: =G25*E25*FloorPlanRate/365 | I25: =D25-E25-F25-H25 | J25: Dec | K25: Direct
A26: 2026 | B26: VIN_U0002026 | C26: 46043 | D26: 22062 | E26: 18611 | F26: 1167 | G26: 67 | H26: =G26*E26*FloorPlanRate/365 | I26: =D26-E26-F26-H26 | J26: Jan | K26: Auction
A27: 2027 | B27: VIN_U0002027 | C27: 46075 | D27: 15887 | E27: 13484 | F27: 424 | G27: 66 | H27: =G27*E27*FloorPlanRate/365 | I27: =D27-E27-F27-H27 | J27: Feb | K27: Direct
A28: 2028 | B28: VIN_U0002028 | C28: 46104 | D28: 20559 | E28: 18112 | F28: 809 | G28: 39 | H28: =G28*E28*FloorPlanRate/365 | I28: =D28-E28-F28-H28 | J28: Mar | K28: Trade-in
A29: 2029 | B29: VIN_U0002029 | C29: 46136 | D29: 23786 | E29: 19949 | F29: 587 | G29: 69 | H29: =G29*E29*FloorPlanRate/365 | I29: =D29-E29-F29-H29 | J29: Apr | K29: Trade-in
A30: 2030 | B30: VIN_U0002030 | C30: 46152 | D30: 19563 | E30: 15669 | F30: 811 | G30: 24 | H30: =G30*E30*FloorPlanRate/365 | I30: =D30-E30-F30-H30 | J30: May | K30: Auction
A31: 2031 | B31: VIN_U0002031 | C31: 46184 | D31: 24016 | E31: 21615 | F31: 403 | G31: 84 | H31: =G31*E31*FloorPlanRate/365 | I31: =D31-E31-F31-H31 | J31: Jun | K31: Trade-in
A40: SUMMARY
A41: Total Adjusted Gross | B41: =SUM(I2:I31)
A42: Weighted Avg DOL | B42: =SUMPRODUCT(G2:G31,D2:D31)/SUM(D2:D31)
A45: Used Gross Jan | B45: =SUMIFS(I2:I31,J2:J31,"Jan")
A46: Used Gross Feb | B46: =SUMIFS(I2:I31,J2:J31,"Feb")
A47: Used Gross Mar | B47: =SUMIFS(I2:I31,J2:J31,"Mar")
A48: Used Gross Apr | B48: =SUMIFS(I2:I31,J2:J31,"Apr")
A49: Used Gross May | B49: =SUMIFS(I2:I31,J2:J31,"May")
A50: Used Gross Jun | B50: =SUMIFS(I2:I31,J2:J31,"Jun")
A51: Used Gross Jul | B51: =SUMIFS(I2:I31,J2:J31,"Jul")
A52: Used Gross Aug | B52: =SUMIFS(I2:I31,J2:J31,"Aug")
A53: Used Gross Sep | B53: =SUMIFS(I2:I31,J2:J31,"Sep")
A54: Used Gross Oct | B54: =SUMIFS(I2:I31,J2:J31,"Oct")
A55: Used Gross Nov | B55: =SUMIFS(I2:I31,J2:J31,"Nov")
A56: Used Gross Dec | B56: =SUMIFS(I2:I31,J2:J31,"Dec")

Sheet F&I Detail
A1: Deal# | B1: Product Type | C1: Product Cost | D1: Product Revenue | E1: Reserve | F1: Month
A2: 1007 | B2: GAP | C2: 370 | D2: 1502 | E2: 298 | F2: Jan
A3: 1032 | B3: GAP | C3: 610 | D3: 1030 | E3: 134 | F3: Feb
A4: 1026 | B4: Warranty | C4: 599 | D4: 1442 | E4: 282 | F4: Mar
A5: 1020 | B5: Maintenance | C5: 769 | D5: 2065 | E5: 129 | F5: Apr
A6: 1014 | B6: Tire & Wheel | C6: 422 | D6: 841 | E6: 346 | F6: May
A7: 1036 | B7: Warranty | C7: 521 | D7: 938 | E7: 75 | F7: Jun
A8: 1039 | B8: Maintenance | C8: 714 | D8: 2101 | E8: 130 | F8: Jul
A9: 1005 | B9: Warranty | C9: 390 | D9: 830 | E9: 354 | F9: Aug
A10: 1006 | B10: GAP | C10: 613 | D10: 1158 | E10: 341 | F10: Sep
A11: 1017 | B11: Warranty | C11: 834 | D11: 1301 | E11: 264 | F11: Oct
A12: 1039 | B12: Tire & Wheel | C12: 467 | D12: 1185 | E12: 392 | F12: Nov
A13: 1022 | B13: GAP | C13: 471 | D13: 1581 | E13: 117 | F13: Dec
... A51: 1034 | B51: Tire & Wheel | C51: 295 | D51: 1076 | E51: 394 | F51: Feb
A55: Total F&I Revenue | B55: =SUM(D2:D51)
A56: Deal Count | B56: =COUNTA(A2:A51)
A57: PVR | B57: =B55/B56
A60: F&I Gross Jan | B60: =SUMIFS(D2:D51,F2:F51,"Jan")-SUMIFS(C2:C51,F2:F51,"Jan")
A61: F&I Gross Feb | B61: =SUMIFS(D2:D51,F2:F51,"Feb")-SUMIFS(C2:C51,F2:F51,"Feb")
A62: F&I Gross Mar | B62: =SUMIFS(D2:D51,F2:F51,"Mar")-SUMIFS(C2:C51,F2:F51,"Mar")
A63: F&I Gross Apr | B63: =SUMIFS(D2:D51,F2:F51,"Apr")-SUMIFS(C2:C51,F2:F51,"Apr")
A64: F&I Gross May | B64: =SUMIFS(D2:D51,F2:F51,"May")-SUMIFS(C2:C51,F2:F51,"May")
A65: F&I Gross Jun | B65: =SUMIFS(D2:D51,F2:F51,"Jun")-SUMIFS(C2:C51,F2:F51,"Jun")
A66: F&I Gross Jul | B66: =SUMIFS(D2:D51,F2:F51,"Jul")-SUMIFS(C2:C51,F2:F51,"Jul")
A67: F&I Gross Aug | B67: =SUMIFS(D2:D51,F2:F51,"Aug")-SUMIFS(C2:C51,F2:F51,"Aug")
A68: F&I Gross Sep | B68: =SUMIFS(D2:D51,F2:F51,"Sep")-SUMIFS(C2:C51,F2:F51,"Sep")
A69: F&I Gross Oct | B69: =SUMIFS(D2:D51,F2:F51,"Oct")-SUMIFS(C2:C51,F2:F51,"Oct")
A70: F&I Gross Nov | B70: =SUMIFS(D2:D51,F2:F51,"Nov")-SUMIFS(C2:C51,F2:F51,"Nov")
A71: F&I Gross Dec | B71: =SUMIFS(D2:D51,F2:F51,"Dec")-SUMIFS(C2:C51,F2:F51,"Dec")

Sheet Service & Parts
A1: RO# | B1: Date | C1: Type | D1: Labor Revenue | E1: Parts Revenue | F1: Labor Cost | G1: Parts Cost | H1: Month
A2: 5002 | B2: 46029 | C2: Customer Pay | D2: 397 | E2: 270 | F2: 202.99 | G2: 156.46 | H2: Jan
A3: 5003 | B3: 46061 | C3: Warranty | D3: 330 | E3: 526 | F3: 155.84 | G3: 370.15 | H3: Feb
A4: 5004 | B4: 46090 | C4: Warranty | D4: 504 | E4: 684 | F4: 234.43 | G4: 474.47 | H4: Mar
A5: 5005 | B5: 46122 | C5: Customer Pay | D5: 586 | E5: 449 | F5: 233.69 | G5: 305.86 | H5: Apr
A6: 5006 | B6: 46153 | C6: Internal | D6: 848 | E6: 149 | F6: 428.82 | G6: 88.47 | H6: May
A7: 5007 | B7: 46185 | C7: Customer Pay | D7: 610 | E7: 515 | F7: 219.63 | G7: 308.92 | H7: Jun
A8: 5008 | B8: 46216 | C8: Internal | D8: 547 | E8: 176 | F8: 279.12 | G8: 120.3 | H8: Jul
A9: 5009 | B9: 46248 | C9: Internal | D9: 689 | E9: 364 | F9: 372.07 | G9: 265.1 | H9: Aug
A10: 5010 | B10: 46280 | C10: Warranty | D10: 816 | E10: 556 | F10: 355.24 | G10: 406.64 | H10: Sep
A11: 5011 | B11: 46311 | C11: Internal | D11: 242 | E11: 526 | F11: 106.48 | G11: 368.39 | H11: Oct
A12: 5012 | B12: 46343 | C12: Warranty | D12: 363 | E12: 573 | F12: 162.23 | G12: 342.57 | H12: Nov
A13: 5013 | B13: 46374 | C13: Internal | D13: 159 | E13: 332 | F13: 63.11 | G13: 204.9 | H13: Dec
... A51: 5051 | B51: 46069 | C51: Internal | D51: 306 | E51: 454 | F51: 149.44 | G51: 277.5 | H51: Feb
A55: Total Labor Gross | B55: =SUM(D2:D51)-SUM(F2:F51)
A56: Total Parts Gross | B56: =SUM(E2:E51)-SUM(G2:G51)
A57: Total Service & Parts Gross | B57: =B55+B56
A60: S&P Gross Jan | B60: =(SUMIFS(D2:D51,H2:H51,"Jan")-SUMIFS(F2:F51,H2:H51,"Jan"))+(SUMIFS(E2:E51,H2:H51,"Jan")-SUMIFS(G2:G51,H2:H51,"Jan"))
A61: S&P Gross Feb | B61: =(SUMIFS(D2:D51,H2:H51,"Feb")-SUMIFS(F2:F51,H2:H51,"Feb"))+(SUMIFS(E2:E51,H2:H51,"Feb")-SUMIFS(G2:G51,H2:H51,"Feb"))
A62: S&P Gross Mar | B62: =(SUMIFS(D2:D51,H2:H51,"Mar")-SUMIFS(F2:F51,H2:H51,"Mar"))+(SUMIFS(E2:E51,H2:H51,"Mar")-SUMIFS(G2:G51,H2:H51,"Mar"))
A63: S&P Gross Apr | B63: =(SUMIFS(D2:D51,H2:H51,"Apr")-SUMIFS(F2:F51,H2:H51,"Apr"))+(SUMIFS(E2:E51,H2:H51,"Apr")-SUMIFS(G2:G51,H2:H51,"Apr"))
A64: S&P Gross May | B64: =(SUMIFS(D2:D51,H2:H51,"May")-SUMIFS(F2:F51,H2:H51,"May"))+(SUMIFS(E2:E51,H2:H51,"May")-SUMIFS(G2:G51,H2:H51,"May"))
A65: S&P Gross Jun | B65: =(SUMIFS(D2:D51,H2:H51,"Jun")-SUMIFS(F2:F51,H2:H51,"Jun"))+(SUMIFS(E2:E51,H2:H51,"Jun")-SUMIFS(G2:G51,H2:H51,"Jun"))
A66: S&P Gross Jul | B66: =(SUMIFS(D2:D51,H2:H51,"Jul")-SUMIFS(F2:F51,H2:H51,"Jul"))+(SUMIFS(E2:E51,H2:H51,"Jul")-SUMIFS(G2:G51,H2:H51,"Jul"))
A67: S&P Gross Aug | B67: =(SUMIFS(D2:D51,H2:H51,"Aug")-SUMIFS(F2:F51,H2:H51,"Aug"))+(SUMIFS(E2:E51,H2:H51,"Aug")-SUMIFS(G2:G51,H2:H51,"Aug"))
A68: S&P Gross Sep | B68: =(SUMIFS(D2:D51,H2:H51,"Sep")-SUMIFS(F2:F51,H2:H51,"Sep"))+(SUMIFS(E2:E51,H2:H51,"Sep")-SUMIFS(G2:G51,H2:H51,"Sep"))
A69: S&P Gross Oct | B69: =(SUMIFS(D2:D51,H2:H51,"Oct")-SUMIFS(F2:F51,H2:H51,"Oct"))+(SUMIFS(E2:E51,H2:H51,"Oct")-SUMIFS(G2:G51,H2:H51,"Oct"))
A70: S&P Gross Nov | B70: =(SUMIFS(D2:D51,H2:H51,"Nov")-SUMIFS(F2:F51,H2:H51,"Nov"))+(SUMIFS(E2:E51,H2:H51,"Nov")-SUMIFS(G2:G51,H2:H51,"Nov"))
A71: S&P Gross Dec | B71: =(SUMIFS(D2:D51,H2:H51,"Dec")-SUMIFS(F2:F51,H2:H51,"Dec"))+(SUMIFS(E2:E51,H2:H51,"Dec")-SUMIFS(G2:G51,H2:H51,"Dec"))
A75: Service Absorption Rate | B75: =B57/'P&L Summary'!B30
